<?xml version="1.0"?>
<sdf version="1.5">
    <model name="willy3">
        <static>false</static>
        <link name="chassis">
            <inertial>
                <mass>10.0</mass>
            </inertial>
            <pose>0 0 .1 0 0 0</pose>
            <collision name="collision">
                <geometry>
                    <box>
                        <size>.4 .2 .1</size>
                    </box>
                </geometry>
            </collision>
            <visual name="visual">
                <geometry>
                    <box>
                        <size>.4 .2 .1</size>
                    </box>
                </geometry>
            </visual>
            <collision name="caster_collision">
                <pose>-0.15 0 -0.05 0 0 0</pose>
                <geometry>
                    <sphere>
                        <radius>.05</radius>
                    </sphere>
                </geometry>
                <surface>
                    <friction>
                        <ode>
                            <mu>0</mu>
                            <mu2>0</mu2>
                            <slip1>1.0</slip1>
                            <slip2>1.0</slip2>
                        </ode>
                    </friction>
                </surface>
            </collision>
            <visual name="caster_visual">
                <pose>-0.15 0 -0.05 0 0 0</pose>
                <geometry>
                    <sphere>
                        <radius>.05</radius>
                    </sphere>
                </geometry>
            </visual>
        </link>
        <link name="left_wheel">
            <pose>0.1 0.13 0.1 0 1.5707 1.5707</pose>
            <collision name="collision">
                <geometry>
                    <cylinder>
                        <radius>.1</radius>
                        <length>.05</length>
                    </cylinder>
                </geometry>
            </collision>
            <visual name="visual">
                <geometry>
                    <cylinder>
                        <radius>.1</radius>
                        <length>.05</length>
                    </cylinder>
                </geometry>
            </visual>
        </link>
        <link name="right_wheel">
            <pose>0.1 -0.13 0.1 0 1.5707 1.5707</pose>
            <collision name="collision">
                <geometry>
                    <cylinder>
                        <radius>.1</radius>
                        <length>.05</length>
                    </cylinder>
                </geometry>
            </collision>
            <visual name="visual">
                <geometry>
                    <cylinder>
                        <radius>.1</radius>
                        <length>.05</length>
                    </cylinder>
                </geometry>
            </visual>
        </link>
        <joint type="revolute" name="left_wheel_hinge">
            <pose>0 0 -0.03 0 0 0</pose>
            <child>left_wheel</child>
            <parent>chassis</parent>
            <axis>
                <xyz>0 0 1</xyz>
            </axis>
        </joint>
        <joint type="revolute" name="right_wheel_hinge">
            <pose>0 0 0.03 0 0 0</pose>
            <child>right_wheel</child>
            <parent>chassis</parent>
            <axis>
                <xyz>0 0 1</xyz>
            </axis>
        </joint>
        <include>
            <uri>model://hokuyo_ros</uri>
            <pose>0.2 0 0.2 0 0 0</pose>
        </include>
        <joint name="hokuyo_joint" type="revolute">
            <child>hokuyo_ros::link</child>
            <parent>chassis</parent>
            <axis>
                <xyz>0 0 1</xyz>
                <limit>
                    <upper>0</upper>
                    <lower>0</lower>
                </limit>
            </axis>
        </joint>        
        <plugin name="differential_drive_controller" filename="libgazebo_ros_diff_drive.so">
            <alwaysOn>true</alwaysOn>
            <updateRate>10</updateRate>
            <leftJoint>left_wheel_hinge</leftJoint>
            <rightJoint>right_wheel_hinge</rightJoint>
            <wheelSeparation>0.26</wheelSeparation>
            <wheelDiameter>0.2</wheelDiameter>
            <wheelTorque>2.5</wheelTorque>
            <torque>5</torque>
            <commandTopic>cmd_vel</commandTopic>
            <odometryTopic>odom</odometryTopic>
            <odometryFrame>odom</odometryFrame>
            <robotBaseFrame>base_link</robotBaseFrame>
            <publishTf>true</publishTf>
            <publishWheelTF>false</publishWheelTF>
            <wheelAcceleration>0</wheelAcceleration>
            <legacyMode>false</legacyMode>
        </plugin>
    </model>
</sdf>
